2022-06-15 17:37:21,777 - Abs测试报告 - INFO - ==========start==========
2022-06-15 17:37:21,778 - Abs测试报告 - INFO - 用例正数开始测试
2022-06-15 17:37:21,779 - Abs测试报告 - INFO - 用例正数测试通过
2022-06-15 17:37:21,791 - Abs测试报告 - ERROR - 数据库断言失败
Traceback (most recent call last):
  File "C:\autoTest\testcases\test_abs.py", line 55, in test_abs
    self.assertTrue(db_res)
  File "C:\Program Files\Python310\lib\unittest\case.py", line 679, in assertTrue
    raise self.failureException(msg)
AssertionError: False is not true
2022-06-15 17:37:21,796 - Abs测试报告 - DEBUG - 执行的SQL是select * from S where sno = "202001"
2022-06-15 17:37:21,801 - Abs测试报告 - INFO - 用例负数开始测试
2022-06-15 17:37:21,802 - Abs测试报告 - ERROR - 用例负数测试失败
Traceback (most recent call last):
  File "C:\autoTest\testcases\test_abs.py", line 44, in test_abs
    self.assertEqual(res, case['expect'])  #断言
  File "C:\Program Files\Python310\lib\unittest\case.py", line 837, in assertEqual
    assertion_func(first, second, msg=msg)
  File "C:\Program Files\Python310\lib\unittest\case.py", line 830, in _baseAssertEqual
    raise self.failureException(msg)
AssertionError: 1 != 2
2022-06-15 17:37:21,806 - Abs测试报告 - INFO - 用例零开始测试
2022-06-15 17:37:21,806 - Abs测试报告 - INFO - 用例零测试通过
2022-06-15 17:37:21,822 - Abs测试报告 - ERROR - 数据库断言失败
Traceback (most recent call last):
  File "C:\autoTest\testcases\test_abs.py", line 55, in test_abs
    self.assertTrue(db_res)
  File "C:\Program Files\Python310\lib\unittest\case.py", line 679, in assertTrue
    raise self.failureException(msg)
AssertionError: False is not true
2022-06-15 17:37:21,824 - Abs测试报告 - DEBUG - 执行的SQL是select * from S where sno = "202003"
2022-06-15 17:37:21,826 - Abs测试报告 - INFO - **********end**********
2022-06-15 17:38:03,238 - Abs测试报告 - INFO - ==========start==========
2022-06-15 17:38:03,239 - Abs测试报告 - INFO - 用例正数开始测试
2022-06-15 17:38:03,240 - Abs测试报告 - INFO - 用例正数测试通过
2022-06-15 17:38:03,249 - Abs测试报告 - ERROR - 数据库断言失败
Traceback (most recent call last):
  File "C:\autoTest\testcases\test_abs.py", line 55, in test_abs
    self.assertTrue(db_res)
  File "C:\Program Files\Python310\lib\unittest\case.py", line 679, in assertTrue
    raise self.failureException(msg)
AssertionError: False is not true
2022-06-15 17:38:03,255 - Abs测试报告 - DEBUG - 执行的SQL是select * from S where sno = "2020001"
2022-06-15 17:38:03,259 - Abs测试报告 - INFO - 用例负数开始测试
2022-06-15 17:38:03,259 - Abs测试报告 - ERROR - 用例负数测试失败
Traceback (most recent call last):
  File "C:\autoTest\testcases\test_abs.py", line 44, in test_abs
    self.assertEqual(res, case['expect'])  #断言
  File "C:\Program Files\Python310\lib\unittest\case.py", line 837, in assertEqual
    assertion_func(first, second, msg=msg)
  File "C:\Program Files\Python310\lib\unittest\case.py", line 830, in _baseAssertEqual
    raise self.failureException(msg)
AssertionError: 1 != 2
2022-06-15 17:38:03,263 - Abs测试报告 - INFO - 用例零开始测试
2022-06-15 17:38:03,264 - Abs测试报告 - INFO - 用例零测试通过
2022-06-15 17:38:03,272 - Abs测试报告 - ERROR - 数据库断言失败
Traceback (most recent call last):
  File "C:\autoTest\testcases\test_abs.py", line 55, in test_abs
    self.assertTrue(db_res)
  File "C:\Program Files\Python310\lib\unittest\case.py", line 679, in assertTrue
    raise self.failureException(msg)
AssertionError: False is not true
2022-06-15 17:38:03,274 - Abs测试报告 - DEBUG - 执行的SQL是select * from S where sno = "2020003"
2022-06-15 17:38:03,276 - Abs测试报告 - INFO - **********end**********
