2022-06-14 10:57:30,563 - Abs测试报告 - INFO - ==========start==========
2022-06-14 10:57:30,564 - Abs测试报告 - INFO - 用例正数开始测试
2022-06-14 10:57:30,565 - Abs测试报告 - INFO - 用例正数测试通过
2022-06-14 10:57:30,565 - Abs测试报告 - INFO - 用例正数执行结束
2022-06-14 10:57:30,566 - Abs测试报告 - INFO - 用例负数开始测试
2022-06-14 10:57:30,567 - Abs测试报告 - ERROR - 用例负数测试失败
Traceback (most recent call last):
  File "C:\autoTest\testcases\test_abs.py", line 42, in test_abs
    self.assertEqual(res, case['expect'])  #断言
  File "C:\Program Files\Python310\lib\unittest\case.py", line 837, in assertEqual
    assertion_func(first, second, msg=msg)
  File "C:\Program Files\Python310\lib\unittest\case.py", line 830, in _baseAssertEqual
    raise self.failureException(msg)
AssertionError: 1 != 2
2022-06-14 10:57:30,574 - Abs测试报告 - INFO - 用例负数执行结束
2022-06-14 10:57:30,580 - Abs测试报告 - INFO - 用例零开始测试
2022-06-14 10:57:30,580 - Abs测试报告 - INFO - 用例零测试通过
2022-06-14 10:57:30,581 - Abs测试报告 - INFO - 用例零执行结束
2022-06-14 10:57:30,582 - Abs测试报告 - INFO - **********end**********
2022-06-14 10:59:31,546 - Abs测试报告 - ERROR - 用例负数测试失败
Traceback (most recent call last):
  File "C:\autoTest\testcases\test_abs.py", line 42, in test_abs
    self.assertEqual(res, case['expect'])  #断言
  File "C:\Program Files\Python310\lib\unittest\case.py", line 837, in assertEqual
    assertion_func(first, second, msg=msg)
  File "C:\Program Files\Python310\lib\unittest\case.py", line 830, in _baseAssertEqual
    raise self.failureException(msg)
AssertionError: 1 != 2
